{"name": "test_negative_user_exist", "status": "failed", "statusDetails": {"message": "AssertionError: That user hasn't been created\nassert False", "trace": "@pytest.mark.negative\n    @pytest.mark.usefixtures(\"setup_newcustomer_screen\")\n    def test_negative_user_exist():\n        try:\n            newCustomer.EnterFirstName(\"Pedro\")\n            newCustomer.EnterLastName(\"Pascal\")\n            newCustomer.EnterEmail(\"mando15042027@gmail.com\")\n            newCustomer.EnterPassw(\"Grokuforever123\")\n            newCustomer.ConfirmPassw(\"Grokuforever123\")\n            newCustomer.PressButtonCreate()\n    \n>           text = f.Sel_by_Xpath(\"//div[@data-bind='html: $parent.prepareMessageForHtml(message.text)'][contains(.,'There is already an account with this email address. If you are sure that it is your email address, click here to get your password and access your account.')]\", t).text\nE           AttributeError: 'NoneType' object has no attribute 'text'\n\nTests\\test_CreateUser.py:40: AttributeError\n\nDuring handling of the above exception, another exception occurred:\n\n    @pytest.mark.negative\n    @pytest.mark.usefixtures(\"setup_newcustomer_screen\")\n    def test_negative_user_exist():\n        try:\n            newCustomer.EnterFirstName(\"Pedro\")\n            newCustomer.EnterLastName(\"Pascal\")\n            newCustomer.EnterEmail(\"mando15042027@gmail.com\")\n            newCustomer.EnterPassw(\"Grokuforever123\")\n            newCustomer.ConfirmPassw(\"Grokuforever123\")\n            newCustomer.PressButtonCreate()\n    \n            text = f.Sel_by_Xpath(\"//div[@data-bind='html: $parent.prepareMessageForHtml(message.text)'][contains(.,'There is already an account with this email address. If you are sure that it is your email address, click here to get your password and access your account.')]\", t).text\n            allure.attach(f.driver.get_screenshot_as_png(), name=\"buscando_nombre\", attachment_type=AttachmentType.PNG)\n    \n        except AttributeError as ex:\n>               assert False, \"That user hasn't been created\"\nE               AssertionError: That user hasn't been created\nE               assert False\n\nTests\\test_CreateUser.py:44: AssertionError"}, "start": 1744753665676, "stop": 1744753683702, "uuid": "627d54b7-7369-48bd-a7ad-499329a7b6e7", "historyId": "69c0373145a5b4c568bc9f8d4765a6ca", "testCaseId": "69c0373145a5b4c568bc9f8d4765a6ca", "fullName": "Tests.test_CreateUser#test_negative_user_exist", "labels": [{"name": "tag", "value": "@pytest.mark.usefixtures('setup_newcustomer_screen')"}, {"name": "tag", "value": "negative"}, {"name": "parentSuite", "value": "Tests"}, {"name": "suite", "value": "test_CreateUser"}, {"name": "host", "value": "JHOHAN-LapTop"}, {"name": "thread", "value": "6732-MainThread"}, {"name": "framework", "value": "pytest"}, {"name": "language", "value": "cpython3"}, {"name": "package", "value": "Tests.test_CreateUser"}]}